Workbook

Sheet PREMISSAS
B1: TIRAMIWAFER — PAINEL DE PREMISSAS (inputs editáveis)
B2: Kopenhagen | Altere os valores amarelos para recalcular toda a planilha
B4: 1. PRODUTO E PREÇOS
B5: Parâmetro | C5: Valor (editável) | D5: Fórmula / Cálculo
B6: Preço de Venda (R$) | C6: 24.9 | D6: ← EDITE AQUI
B7: Alíquota Simples Nacional | C7: 0.107 | D7: ← EDITE AQUI
B8: COGS — Insumos (R$/un) | C8: 7.47 | D8: ← EDITE AQUI
B9: ICMS ST (R$/un) | C9: 0.16 | D9: ← EDITE AQUI
B10: Calculado automaticamente (não edite)
B11: Impostos (R$/un) | C11: =C6*C7
B12: Receita Líquida (R$/un) | C12: =C6*(1-C7)
B13: COGS Total (R$/un) | C13: =C8+C9
B14: Margem de Contribuição | C14: =C6*(1-C7)-C8-C9
B15: CMC % (vs Receita Bruta) | C15: =(C6*(1-C7)-C8-C9)/C6
B16: CMC % (vs Rec. Líquida) | C16: =(C6*(1-C7)-C8-C9)/(C6*(1-C7))
B17: Target Mínimo Kopenhagen | C17: 0.48
B18: Folga vs Target | C18: =(C6*(1-C7)-C8-C9)/C6-0.48
B20: 2. SEGMENTAÇÃO DE LOJAS
B21: Segmento | C21: Nº Lojas | D21: Cupons/dia | E21: TM Médio (R$) | F21: Penet. Pessimista | G21: Penet. Realista | H21: Penet. Otimista
B22: Alta Performance | C22: 7 | D22: 44 | E22: 35.81 | F22: 0.03 | G22: 0.05 | H22: 0.08
B23: Média Performance | C23: 306 | D23: 177 | E23: 25.38 | F23: 0.02 | G23: 0.035 | H23: 0.055
B24: Baixa Performance | C24: 487 | D24: 123 | E24: 22.97 | F24: 0.015 | G24: 0.025 | H24: 0.04
B25: TOTAL REDE | C25: =C22+C23+C24 | D25: — | E25: — | F25: — | G25: — | H25: —
B27: 3. RAMP-UP MENSAL (% do volume maduro — editável)
C28: Jan | D28: Fev | E28: Mar | F28: Abr | G28: Mai | H28: Jun | I28: Jul | J28: Ago | K28: Set | L28: Out | M28: Nov | N28: Dez
B29: Fator de Ramp-up | C29: 0.25 | D29: 0.45 | E29: 0.65 | F29: 0.8 | G29: 0.92 | H29: 1 | I29: 1 | J29: 1 | K29: 1 | L29: 1 | M29: 1 | N29: 1
B31: 4. INVESTIMENTO DE LANÇAMENTO
B32: Item | C32: Valor (R$) | D32: Tipo
B33: POS Materials (R$80 × 800 lojas) | C33: 64000 | D33: One-time
B34: Campanha Digital | C34: 200000 | D34: One-time
B35: Sampling Abertura | C35: 16000 | D35: One-time
B36: Produção Conteúdo (foto/vídeo) | C36: 80000 | D36: One-time
B37: PR / Imprensa | C37: 30000 | D37: One-time
B38: Materiais Treinamento | C38: 8000 | D38: One-time
B39: Contingência | C39: 52000 | D39: One-time
B40: Marketing Recorrente (por mês) | C40: 50000 | D40: Recorrente/mês
B41: TOTAL LANÇAMENTO (one-time) | C41: =C33+C34+C35+C36+C37+C38+C39 | D41: —

Sheet PROJEÇÃO 12M
B1: TIRAMIWAFER — PROJEÇÃO DE VENDAS 12 MESES | FÓRMULAS EDITÁVEIS
B2: Todos os valores calculados via fórmulas que referenciam a aba PREMISSAS — altere lá para recalcular tudo
B4: CENÁRIO ATIVO: | D4: R | E4: ← Digite: P (pessimista) | R (realista) | O (otimista)
B6: ══ CENÁRIO PESSIMISTA ══ (P)
B7: VOLUME (unidades)
B8: Segmento | C8: Jan | D8: Fev | E8: Mar | F8: Abr | G8: Mai | H8: Jun | I8: Jul | J8: Ago | K8: Set | L8: Out | M8: Nov | N8: Dez | O8: TOTAL ANO
B9: Alta (7 lojas) | C9: =ROUND(PREMISSAS!C22*PREMISSAS!D22*PREMISSAS!F22*26*PREMISSAS!C29,0) | D9: =ROUND(PREMISSAS!C22*PREMISSAS!D22*PREMISSAS!F22*26*PREMISSAS!D29,0) | E9: =ROUND(PREMISSAS!C22*PREMISSAS!D22*PREMISSAS!F22*26*PREMISSAS!E29,0) | F9: =ROUND(PREMISSAS!C22*PREMISSAS!D22*PREMISSAS!F22*26*PREMISSAS!F29,0) | G9: =ROUND(PREMISSAS!C22*PREMISSAS!D22*PREMISSAS!F22*26*PREMISSAS!G29,0) | H9: =ROUND(PREMISSAS!C22*PREMISSAS!D22*PREMISSAS!F22*26*PREMISSAS!H29,0) | I9: =ROUND(PREMISSAS!C22*PREMISSAS!D22*PREMISSAS!F22*26*PREMISSAS!I29,0) | J9: =ROUND(PREMISSAS!C22*PREMISSAS!D22*PREMISSAS!F22*26*PREMISSAS!J29,0) | K9: =ROUND(PREMISSAS!C22*PREMISSAS!D22*PREMISSAS!F22*26*PREMISSAS!K29,0) | L9: =ROUND(PREMISSAS!C22*PREMISSAS!D22*PREMISSAS!F22*26*PREMISSAS!L29,0) | M9: =ROUND(PREMISSAS!C22*PREMISSAS!D22*PREMISSAS!F22*26*PREMISSAS!M29,0) | N9: =ROUND(PREMISSAS!C22*PREMISSAS!D22*PREMISSAS!F22*26*PREMISSAS!N29,0) | O9: =SUM(C9:N9)
B10: Média (306 lojas) | C10: =ROUND(PREMISSAS!C23*PREMISSAS!D23*PREMISSAS!F23*26*PREMISSAS!C29,0) | D10: =ROUND(PREMISSAS!C23*PREMISSAS!D23*PREMISSAS!F23*26*PREMISSAS!D29,0) | E10: =ROUND(PREMISSAS!C23*PREMISSAS!D23*PREMISSAS!F23*26*PREMISSAS!E29,0) | F10: =ROUND(PREMISSAS!C23*PREMISSAS!D23*PREMISSAS!F23*26*PREMISSAS!F29,0) | G10: =ROUND(PREMISSAS!C23*PREMISSAS!D23*PREMISSAS!F23*26*PREMISSAS!G29,0) | H10: =ROUND(PREMISSAS!C23*PREMISSAS!D23*PREMISSAS!F23*26*PREMISSAS!H29,0) | I10: =ROUND(PREMISSAS!C23*PREMISSAS!D23*PREMISSAS!F23*26*PREMISSAS!I29,0) | J10: =ROUND(PREMISSAS!C23*PREMISSAS!D23*PREMISSAS!F23*26*PREMISSAS!J29,0) | K10: =ROUND(PREMISSAS!C23*PREMISSAS!D23*PREMISSAS!F23*26*PREMISSAS!K29,0) | L10: =ROUND(PREMISSAS!C23*PREMISSAS!D23*PREMISSAS!F23*26*PREMISSAS!L29,0) | M10: =ROUND(PREMISSAS!C23*PREMISSAS!D23*PREMISSAS!F23*26*PREMISSAS!M29,0) | N10: =ROUND(PREMISSAS!C23*PREMISSAS!D23*PREMISSAS!F23*26*PREMISSAS!N29,0) | O10: =SUM(C10:N10)
B11: Baixa (487 lojas) | C11: =ROUND(PREMISSAS!C24*PREMISSAS!D24*PREMISSAS!F24*26*PREMISSAS!C29,0) | D11: =ROUND(PREMISSAS!C24*PREMISSAS!D24*PREMISSAS!F24*26*PREMISSAS!D29,0) | E11: =ROUND(PREMISSAS!C24*PREMISSAS!D24*PREMISSAS!F24*26*PREMISSAS!E29,0) | F11: =ROUND(PREMISSAS!C24*PREMISSAS!D24*PREMISSAS!F24*26*PREMISSAS!F29,0) | G11: =ROUND(PREMISSAS!C24*PREMISSAS!D24*PREMISSAS!F24*26*PREMISSAS!G29,0) | H11: =ROUND(PREMISSAS!C24*PREMISSAS!D24*PREMISSAS!F24*26*PREMISSAS!H29,0) | I11: =ROUND(PREMISSAS!C24*PREMISSAS!D24*PREMISSAS!F24*26*PREMISSAS!I29,0) | J11: =ROUND(PREMISSAS!C24*PREMISSAS!D24*PREMISSAS!F24*26*PREMISSAS!J29,0) | K11: =ROUND(PREMISSAS!C24*PREMISSAS!D24*PREMISSAS!F24*26*PREMISSAS!K29,0) | L11: =ROUND(PREMISSAS!C24*PREMISSAS!D24*PREMISSAS!F24*26*PREMISSAS!L29,0) | M11: =ROUND(PREMISSAS!C24*PREMISSAS!D24*PREMISSAS!F24*26*PREMISSAS!M29,0) | N11: =ROUND(PREMISSAS!C24*PREMISSAS!D24*PREMISSAS!F24*26*PREMISSAS!N29,0) | O11: =SUM(C11:N11)
B12: TOTAL REDE (un) | C12: =C9+C10+C11 | D12: =D9+D10+D11 | E12: =E9+E10+E11 | F12: =F9+F10+F11 | G12: =G9+G10+G11 | H12: =H9+H10+H11 | I12: =I9+I10+I11 | J12: =J9+J10+J11 | ... N12: =N9+N10+N11 | O12: =SUM(C12:N12)
B13: ↳ Un/loja/dia (média rede) | C13: =ROUND(C12/800/26,1) | D13: =ROUND(D12/800/26,1) | E13: =ROUND(E12/800/26,1) | F13: =ROUND(F12/800/26,1) | G13: =ROUND(G12/800/26,1) | H13: =ROUND(H12/800/26,1) | I13: =ROUND(I12/800/26,1) | J13: =ROUND(J12/800/26,1) | ... N13: =ROUND(N12/800/26,1) | O13: =ROUND(O12/800/12/26,1)
B14: DRE — REDE COMPLETA (R$)
B15: Linha DRE | C15: Jan | D15: Fev | E15: Mar | F15: Abr | G15: Mai | H15: Jun | I15: Jul | J15: Ago | K15: Set | L15: Out | M15: Nov | N15: Dez | O15: TOTAL ANO
B16: Receita Bruta | C16: =C12*PREMISSAS!C6 | D16: =D12*PREMISSAS!C6 | E16: =E12*PREMISSAS!C6 | F16: =F12*PREMISSAS!C6 | G16: =G12*PREMISSAS!C6 | H16: =H12*PREMISSAS!C6 | I16: =I12*PREMISSAS!C6 | J16: =J12*PREMISSAS!C6 | K16: =K12*PREMISSAS!C6 | L16: =L12*PREMISSAS!C6 | M16: =M12*PREMISSAS!C6 | N16: =N12*PREMISSAS!C6 | O16: =SUM(C16:N16)
B17: (-) Impostos (10.7%) | C17: =-C12*PREMISSAS!C6*PREMISSAS!C7 | D17: =-D12*PREMISSAS!C6*PREMISSAS!C7 | E17: =-E12*PREMISSAS!C6*PREMISSAS!C7 | F17: =-F12*PREMISSAS!C6*PREMISSAS!C7 | G17: =-G12*PREMISSAS!C6*PREMISSAS!C7 | H17: =-H12*PREMISSAS!C6*PREMISSAS!C7 | I17: =-I12*PREMISSAS!C6*PREMISSAS!C7 | J17: =-J12*PREMISSAS!C6*PREMISSAS!C7 | K17: =-K12*PREMISSAS!C6*PREMISSAS!C7 | L17: =-L12*PREMISSAS!C6*PREMISSAS!C7 | M17: =-M12*PREMISSAS!C6*PREMISSAS!C7 | N17: =-N12*PREMISSAS!C6*PREMISSAS!C7 | O17: =SUM(C17:N17)
B18: Receita Líquida (NNS) | C18: =C16+C17 | D18: =D16+D17 | E18: =E16+E17 | F18: =F16+F17 | G18: =G16+G17 | H18: =H16+H17 | I18: =I16+I17 | J18: =J16+J17 | ... N18: =N16+N17 | O18: =SUM(C18:N18)
B19: (-) COGS (insumos + ICMS ST) | C19: =-C12*(PREMISSAS!C8+PREMISSAS!C9) | D19: =-D12*(PREMISSAS!C8+PREMISSAS!C9) | E19: =-E12*(PREMISSAS!C8+PREMISSAS!C9) | F19: =-F12*(PREMISSAS!C8+PREMISSAS!C9) | G19: =-G12*(PREMISSAS!C8+PREMISSAS!C9) | H19: =-H12*(PREMISSAS!C8+PREMISSAS!C9) | I19: =-I12*(PREMISSAS!C8+PREMISSAS!C9) | J19: =-J12*(PREMISSAS!C8+PREMISSAS!C9) | K19: =-K12*(PREMISSAS!C8+PREMISSAS!C9) | L19: =-L12*(PREMISSAS!C8+PREMISSAS!C9) | M19: =-M12*(PREMISSAS!C8+PREMISSAS!C9) | N19: =-N12*(PREMISSAS!C8+PREMISSAS!C9) | O19: =SUM(C19:N19)
B20: MARGEM DE CONTRIBUIÇÃO (CMC) | C20: =C18+C19 | D20: =D18+D19 | E20: =E18+E19 | F20: =F18+F19 | G20: =G18+G19 | H20: =H18+H19 | I20: =I18+I19 | J20: =J18+J19 | ... N20: =N18+N19 | O20: =SUM(C20:N20)
B21: CMC % (vs Receita Bruta) | C21: =IF(C16<>0,C20/C16,0) | D21: =IF(D16<>0,D20/D16,0) | E21: =IF(E16<>0,E20/E16,0) | F21: =IF(F16<>0,F20/F16,0) | G21: =IF(G16<>0,G20/G16,0) | H21: =IF(H16<>0,H20/H16,0) | I21: =IF(I16<>0,I20/I16,0) | J21: =IF(J16<>0,J20/J16,0) | ... N21: =IF(N16<>0,N20/N16,0) | O21: =AVERAGE(C21:N21)
B22: (-) Marketing Recorrente | C22: =-PREMISSAS!C40 | D22: =-PREMISSAS!C40 | E22: =-PREMISSAS!C40 | F22: =-PREMISSAS!C40 | G22: =-PREMISSAS!C40 | H22: =-PREMISSAS!C40 | I22: =-PREMISSAS!C40 | J22: =-PREMISSAS!C40 | K22: =-PREMISSAS!C40 | L22: =-PREMISSAS!C40 | M22: =-PREMISSAS!C40 | N22: =-PREMISSAS!C40 | O22: =SUM(C22:N22)
B23: (-) Invest. Lançamento (mês 1) | C23: =IF(1=1,-PREMISSAS!C41,0) | D23: =IF(2=1,-PREMISSAS!C41,0) | E23: =IF(3=1,-PREMISSAS!C41,0) | F23: =IF(4=1,-PREMISSAS!C41,0) | G23: =IF(5=1,-PREMISSAS!C41,0) | H23: =IF(6=1,-PREMISSAS!C41,0) | I23: =IF(7=1,-PREMISSAS!C41,0) | J23: =IF(8=1,-PREMISSAS!C41,0) | K23: =IF(9=1,-PREMISSAS!C41,0) | L23: =IF(10=1,-PREMISSAS!C41,0) | M23: =IF(11=1,-PREMISSAS!C41,0) | N23: =IF(12=1,-PREMISSAS!C41,0) | O23: =SUM(C23:N23)
B24: EBITDA | C24: =C20+C22+C23 | D24: =D20+D22+D23 | E24: =E20+E22+E23 | F24: =F20+F22+F23 | G24: =G20+G22+G23 | H24: =H20+H22+H23 | I24: =I20+I22+I23 | J24: =J20+J22+J23 | ... N24: =N20+N22+N23 | O24: =SUM(C24:N24)
B25: EBITDA % (vs Rec. Bruta) | C25: =IF(C16<>0,C24/C16,0) | D25: =IF(D16<>0,D24/D16,0) | E25: =IF(E16<>0,E24/E16,0) | F25: =IF(F16<>0,F24/F16,0) | G25: =IF(G16<>0,G24/G16,0) | H25: =IF(H16<>0,H24/H16,0) | I25: =IF(I16<>0,I24/I16,0) | J25: =IF(J16<>0,J24/J16,0) | ... N25: =IF(N16<>0,N24/N16,0) | O25: =AVERAGE(C25:N25)
B28: ══ CENÁRIO REALISTA ══ (R)
B29: VOLUME (unidades)
B30: Segmento | C30: Jan | D30: Fev | E30: Mar | F30: Abr | G30: Mai | H30: Jun | I30: Jul | J30: Ago | K30: Set | L30: Out | M30: Nov | N30: Dez | O30: TOTAL ANO
B31: Alta (7 lojas) | C31: =ROUND(PREMISSAS!C22*PREMISSAS!D22*PREMISSAS!G22*26*PREMISSAS!C29,0) | D31: =ROUND(PREMISSAS!C22*PREMISSAS!D22*PREMISSAS!G22*26*PREMISSAS!D29,0) | E31: =ROUND(PREMISSAS!C22*PREMISSAS!D22*PREMISSAS!G22*26*PREMISSAS!E29,0) | F31: =ROUND(PREMISSAS!C22*PREMISSAS!D22*PREMISSAS!G22*26*PREMISSAS!F29,0) | G31: =ROUND(PREMISSAS!C22*PREMISSAS!D22*PREMISSAS!G22*26*PREMISSAS!G29,0) | H31: =ROUND(PREMISSAS!C22*PREMISSAS!D22*PREMISSAS!G22*26*PREMISSAS!H29,0) | I31: =ROUND(PREMISSAS!C22*PREMISSAS!D22*PREMISSAS!G22*26*PREMISSAS!I29,0) | J31: =ROUND(PREMISSAS!C22*PREMISSAS!D22*PREMISSAS!G22*26*PREMISSAS!J29,0) | K31: =ROUND(PREMISSAS!C22*PREMISSAS!D22*PREMISSAS!G22*26*PREMISSAS!K29,0) | L31: =ROUND(PREMISSAS!C22*PREMISSAS!D22*PREMISSAS!G22*26*PREMISSAS!L29,0) | M31: =ROUND(PREMISSAS!C22*PREMISSAS!D22*PREMISSAS!G22*26*PREMISSAS!M29,0) | N31: =ROUND(PREMISSAS!C22*PREMISSAS!D22*PREMISSAS!G22*26*PREMISSAS!N29,0) | O31: =SUM(C31:N31)
B32: Média (306 lojas) | C32: =ROUND(PREMISSAS!C23*PREMISSAS!D23*PREMISSAS!G23*26*PREMISSAS!C29,0) | D32: =ROUND(PREMISSAS!C23*PREMISSAS!D23*PREMISSAS!G23*26*PREMISSAS!D29,0) | E32: =ROUND(PREMISSAS!C23*PREMISSAS!D23*PREMISSAS!G23*26*PREMISSAS!E29,0) | F32: =ROUND(PREMISSAS!C23*PREMISSAS!D23*PREMISSAS!G23*26*PREMISSAS!F29,0) | G32: =ROUND(PREMISSAS!C23*PREMISSAS!D23*PREMISSAS!G23*26*PREMISSAS!G29,0) | H32: =ROUND(PREMISSAS!C23*PREMISSAS!D23*PREMISSAS!G23*26*PREMISSAS!H29,0) | I32: =ROUND(PREMISSAS!C23*PREMISSAS!D23*PREMISSAS!G23*26*PREMISSAS!I29,0) | J32: =ROUND(PREMISSAS!C23*PREMISSAS!D23*PREMISSAS!G23*26*PREMISSAS!J29,0) | K32: =ROUND(PREMISSAS!C23*PREMISSAS!D23*PREMISSAS!G23*26*PREMISSAS!K29,0) | L32: =ROUND(PREMISSAS!C23*PREMISSAS!D23*PREMISSAS!G23*26*PREMISSAS!L29,0) | M32: =ROUND(PREMISSAS!C23*PREMISSAS!D23*PREMISSAS!G23*26*PREMISSAS!M29,0) | N32: =ROUND(PREMISSAS!C23*PREMISSAS!D23*PREMISSAS!G23*26*PREMISSAS!N29,0) | O32: =SUM(C32:N32)
B33: Baixa (487 lojas) | C33: =ROUND(PREMISSAS!C24*PREMISSAS!D24*PREMISSAS!G24*26*PREMISSAS!C29,0) | D33: =ROUND(PREMISSAS!C24*PREMISSAS!D24*PREMISSAS!G24*26*PREMISSAS!D29,0) | E33: =ROUND(PREMISSAS!C24*PREMISSAS!D24*PREMISSAS!G24*26*PREMISSAS!E29,0) | F33: =ROUND(PREMISSAS!C24*PREMISSAS!D24*PREMISSAS!G24*26*PREMISSAS!F29,0) | G33: =ROUND(PREMISSAS!C24*PREMISSAS!D24*PREMISSAS!G24*26*PREMISSAS!G29,0) | H33: =ROUND(PREMISSAS!C24*PREMISSAS!D24*PREMISSAS!G24*26*PREMISSAS!H29,0) | I33: =ROUND(PREMISSAS!C24*PREMISSAS!D24*PREMISSAS!G24*26*PREMISSAS!I29,0) | J33: =ROUND(PREMISSAS!C24*PREMISSAS!D24*PREMISSAS!G24*26*PREMISSAS!J29,0) | K33: =ROUND(PREMISSAS!C24*PREMISSAS!D24*PREMISSAS!G24*26*PREMISSAS!K29,0) | L33: =ROUND(PREMISSAS!C24*PREMISSAS!D24*PREMISSAS!G24*26*PREMISSAS!L29,0) | M33: =ROUND(PREMISSAS!C24*PREMISSAS!D24*PREMISSAS!G24*26*PREMISSAS!M29,0) | N33: =ROUND(PREMISSAS!C24*PREMISSAS!D24*PREMISSAS!G24*26*PREMISSAS!N29,0) | O33: =SUM(C33:N33)
B34: TOTAL REDE (un) | C34: =C31+C32+C33 | D34: =D31+D32+D33 | E34: =E31+E32+E33 | F34: =F31+F32+F33 | G34: =G31+G32+G33 | H34: =H31+H32+H33 | I34: =I31+I32+I33 | J34: =J31+J32+J33 | ... N34: =N31+N32+N33 | O34: =SUM(C34:N34)
B35: ↳ Un/loja/dia (média rede) | C35: =ROUND(C34/800/26,1) | D35: =ROUND(D34/800/26,1) | E35: =ROUND(E34/800/26,1) | F35: =ROUND(F34/800/26,1) | G35: =ROUND(G34/800/26,1) | H35: =ROUND(H34/800/26,1) | I35: =ROUND(I34/800/26,1) | J35: =ROUND(J34/800/26,1) | ... N35: =ROUND(N34/800/26,1) | O35: =ROUND(O34/800/12/26,1)
B36: DRE — REDE COMPLETA (R$)
B37: Linha DRE | C37: Jan | D37: Fev | E37: Mar | F37: Abr | G37: Mai | H37: Jun | I37: Jul | J37: Ago | K37: Set | L37: Out | M37: Nov | N37: Dez | O37: TOTAL ANO
B38: Receita Bruta | C38: =C34*PREMISSAS!C6 | D38: =D34*PREMISSAS!C6 | E38: =E34*PREMISSAS!C6 | F38: =F34*PREMISSAS!C6 | G38: =G34*PREMISSAS!C6 | H38: =H34*PREMISSAS!C6 | I38: =I34*PREMISSAS!C6 | J38: =J34*PREMISSAS!C6 | K38: =K34*PREMISSAS!C6 | L38: =L34*PREMISSAS!C6 | M38: =M34*PREMISSAS!C6 | N38: =N34*PREMISSAS!C6 | O38: =SUM(C38:N38)
B39: (-) Impostos (10.7%) | C39: =-C34*PREMISSAS!C6*PREMISSAS!C7 | D39: =-D34*PREMISSAS!C6*PREMISSAS!C7 | E39: =-E34*PREMISSAS!C6*PREMISSAS!C7 | F39: =-F34*PREMISSAS!C6*PREMISSAS!C7 | G39: =-G34*PREMISSAS!C6*PREMISSAS!C7 | H39: =-H34*PREMISSAS!C6*PREMISSAS!C7 | I39: =-I34*PREMISSAS!C6*PREMISSAS!C7 | J39: =-J34*PREMISSAS!C6*PREMISSAS!C7 | K39: =-K34*PREMISSAS!C6*PREMISSAS!C7 | L39: =-L34*PREMISSAS!C6*PREMISSAS!C7 | M39: =-M34*PREMISSAS!C6*PREMISSAS!C7 | N39: =-N34*PREMISSAS!C6*PREMISSAS!C7 | O39: =SUM(C39:N39)
B40: Receita Líquida (NNS) | C40: =C38+C39 | D40: =D38+D39 | E40: =E38+E39 | F40: =F38+F39 | G40: =G38+G39 | H40: =H38+H39 | I40: =I38+I39 | J40: =J38+J39 | ... N40: =N38+N39 | O40: =SUM(C40:N40)
B41: (-) COGS (insumos + ICMS ST) | C41: =-C34*(PREMISSAS!C8+PREMISSAS!C9) | D41: =-D34*(PREMISSAS!C8+PREMISSAS!C9) | E41: =-E34*(PREMISSAS!C8+PREMISSAS!C9) | F41: =-F34*(PREMISSAS!C8+PREMISSAS!C9) | G41: =-G34*(PREMISSAS!C8+PREMISSAS!C9) | H41: =-H34*(PREMISSAS!C8+PREMISSAS!C9) | I41: =-I34*(PREMISSAS!C8+PREMISSAS!C9) | J41: =-J34*(PREMISSAS!C8+PREMISSAS!C9) | K41: =-K34*(PREMISSAS!C8+PREMISSAS!C9) | L41: =-L34*(PREMISSAS!C8+PREMISSAS!C9) | M41: =-M34*(PREMISSAS!C8+PREMISSAS!C9) | N41: =-N34*(PREMISSAS!C8+PREMISSAS!C9) | O41: =SUM(C41:N41)
B42: MARGEM DE CONTRIBUIÇÃO (CMC) | C42: =C40+C41 | D42: =D40+D41 | E42: =E40+E41 | F42: =F40+F41 | G42: =G40+G41 | H42: =H40+H41 | I42: =I40+I41 | J42: =J40+J41 | ... N42: =N40+N41 | O42: =SUM(C42:N42)
B43: CMC % (vs Receita Bruta) | C43: =IF(C38<>0,C42/C38,0) | D43: =IF(D38<>0,D42/D38,0) | E43: =IF(E38<>0,E42/E38,0) | F43: =IF(F38<>0,F42/F38,0) | G43: =IF(G38<>0,G42/G38,0) | H43: =IF(H38<>0,H42/H38,0) | I43: =IF(I38<>0,I42/I38,0) | J43: =IF(J38<>0,J42/J38,0) | ... N43: =IF(N38<>0,N42/N38,0) | O43: =AVERAGE(C43:N43)
B44: (-) Marketing Recorrente | C44: =-PREMISSAS!C40 | D44: =-PREMISSAS!C40 | E44: =-PREMISSAS!C40 | F44: =-PREMISSAS!C40 | G44: =-PREMISSAS!C40 | H44: =-PREMISSAS!C40 | I44: =-PREMISSAS!C40 | J44: =-PREMISSAS!C40 | K44: =-PREMISSAS!C40 | L44: =-PREMISSAS!C40 | M44: =-PREMISSAS!C40 | N44: =-PREMISSAS!C40 | O44: =SUM(C44:N44)
...

Sheet PONTO DE EQUILÍBRIO
B1: TIRAMIWAFER — PONTO DE EQUILÍBRIO (com fórmulas)
B3: Indicador | C3: Fórmula | D3: Valor Calculado | E3: Referência
B4: CMC por Unidade (R$) | C4: =PREMISSAS!C14 | D4: =PREMISSAS!C14 | E4: Calc. em PREMISSAS
B5: Investimento Total (R$) | C5: =PREMISSAS!C41 | D5: =PREMISSAS!C41 | E5: Calc. em PREMISSAS
B6: PE — Unidades Rede Total | C6: ver fórmula na célula | D6: =ROUND(PREMISSAS!C41/PREMISSAS!C14,0) | E6: Invest ÷ CMC/un
B7: PE — Unidades por Loja (÷800) | C7: ver fórmula na célula | D7: =ROUND(PREMISSAS!C41/PREMISSAS!C14/800,0) | E7: PE total ÷ 800 lojas
B10: RECUPERAÇÃO ACUMULADA DO INVESTIMENTO (Cenário Realista)
B11: Mês | C11: Vol. Rede (un) | D11: CMC Mensal (R$) | E11: CMC Acumulado (R$) | F11: % Recuperado
B12: Jan | C12: =IFERROR('PROJEÇÃO 12M'!C&"ver planilha",0)
B13: Fev | C13: =IFERROR('PROJEÇÃO 12M'!D&"ver planilha",0)
B14: Mar | C14: =IFERROR('PROJEÇÃO 12M'!E&"ver planilha",0)
B15: Abr | C15: =IFERROR('PROJEÇÃO 12M'!F&"ver planilha",0)
B16: Mai | C16: =IFERROR('PROJEÇÃO 12M'!G&"ver planilha",0)
B17: Jun | C17: =IFERROR('PROJEÇÃO 12M'!H&"ver planilha",0)
B18: Jul | C18: =IFERROR('PROJEÇÃO 12M'!I&"ver planilha",0)
B19: Ago | C19: =IFERROR('PROJEÇÃO 12M'!J&"ver planilha",0)
B20: Set | C20: =IFERROR('PROJEÇÃO 12M'!K&"ver planilha",0)
B21: Out | C21: =IFERROR('PROJEÇÃO 12M'!L&"ver planilha",0)
B22: Nov | C22: =IFERROR('PROJEÇÃO 12M'!M&"ver planilha",0)
B23: Dez | C23: =IFERROR('PROJEÇÃO 12M'!N&"ver planilha",0)

Sheet MARGEM UNITÁRIA
B1: TIRAMIWAFER — CASCATA DE MARGEM UNITÁRIA (fórmulas)
B3: Linha | C3: R$/unidade | D3: % Preço Venda | E3: % Rec. Líquida | F3: Nota
B4: Preço de Venda | C4: =PREMISSAS!C6 | D4: =C4/PREMISSAS!C6 | F4: Editável em PREMISSAS
B5: (-) Impostos Simples Nacional | C5: =-PREMISSAS!C6*PREMISSAS!C7 | D5: =C5/PREMISSAS!C6 | F5: Alíquota editável em PREMISSAS
B6: Receita Líquida (NNS) | C6: =C4+C5 | D6: =C6/C4 | E6: =1
B7: (-) Insumos (CPV) | C7: =-PREMISSAS!C8 | D7: =C7/C4 | E7: =C7/C6 | F7: Chantilly + Wafer + Chocolate
B8: (-) ICMS ST | C8: =-PREMISSAS!C9 | D8: =C8/C4 | E8: =C8/C6 | F8: Substituição tributária
B9: COGS Total | C9: =C7+C8 | D9: =C9/C4 | E9: =C9/C6
B10: MARGEM DE CONTRIBUIÇÃO (CMC) | C10: =C6+C9 | D10: =C10/C4 | E10: =C10/C6 | F10: ✅ Target Mínimo: 48% da RB
B11: Target Mínimo Kopenhagen (48%) | C11: =0.48*C4 | D11: =0.48 | E11: =C11/C6 | F11: KPI Corporativo
B12: Folga vs Target | C12: =C10-C11 | D12: =C12/C4 | E12: =C12/C6 | F12: Positivo = acima do target
